Workbook

Sheet Monatsvergleich
A1: Dynamisch vs. Festpreis – Monat für Monat
A2: Zeitraum 16.10.2024 – 15.10.2026 (Okt. 2024 und Okt. 2026 sind Teilmonate). Grün = dynamisch war günstiger.
A4: Monat | B4: Tage | C4: Ø Börsenpreis (ct/kWh netto) | D4: Ø Endpreis dynamisch, einfach (ct/kWh) | E4: Ø Endpreis dynamisch, nach Verbrauchsprofil (ct/kWh) | F4: Festpreis (ct/kWh) | G4: Verbrauch (kWh) | H4: Kosten dynamisch (€) | I4: Kosten fest (€) | J4: Ersparnis dynamisch (€) | K4: Stunden günstiger als Festpreis
A5: 2024-10 | B5: =ROUND(COUNTIF(Stundenpreise!$H$2:$H$17521,A5)/24,0) -> 16 | C5: =AVERAGEIF(Stundenpreise!$H$2:$H$17521,A5,Stundenpreise!$D$2:$D$17521)/10 -> 9.4825896 | D5: =AVERAGEIF(Stundenpreise!$H$2:$H$17521,A5,Stundenpreise!$F$2:$F$17521) -> 33.484922 | E5: =SUMIF(Stundenpreise!$H$2:$H$17521,A5,Stundenpreise!$J$2:$J$17521)/SUMIF(Stundenpreise!$H$2:$H$17521,A5,Stundenpreise!$I$2:$I$17521) -> 34.080939 | F5: =Einstellungen!$B$5 -> 29 | G5: =Einstellungen!$B$9*B5/365 -> 153.42466 | H5: =G5*E5/100+(Einstellungen!$B$7+Einstellungen!$B$8/12)*B5/(365/12) -> 56.759797 | I5: =G5*F5/100+Einstellungen!$B$6*B5/(365/12) -> 50.805479 | J5: =I5-H5 -> -5.9543175 | K5: =COUNTIFS(Stundenpreise!$H$2:$H$17521,A5,Stundenpreise!$G$2:$G$17521,"ja")/COUNTIF(Stundenpreise!$H$2:$H$17521,A5) -> 0.13246753
A6: 2024-11 | B6: =ROUND(COUNTIF(Stundenpreise!$H$2:$H$17521,A6)/24,0) -> 30 | C6: =AVERAGEIF(Stundenpreise!$H$2:$H$17521,A6,Stundenpreise!$D$2:$D$17521)/10 -> 11.390644 | D6: =AVERAGEIF(Stundenpreise!$H$2:$H$17521,A6,Stundenpreise!$F$2:$F$17521) -> 35.755507 | E6: =SUMIF(Stundenpreise!$H$2:$H$17521,A6,Stundenpreise!$J$2:$J$17521)/SUMIF(Stundenpreise!$H$2:$H$17521,A6,Stundenpreise!$I$2:$I$17521) -> 36.453529 | F6: =Einstellungen!$B$5 -> 29 | G6: =Einstellungen!$B$9*B6/365 -> 287.67123 | H6: =G6*E6/100+(Einstellungen!$B$7+Einstellungen!$B$8/12)*B6/(365/12) -> 113.24988 | I6: =G6*F6/100+Einstellungen!$B$6*B6/(365/12) -> 95.260274 | J6: =I6-H6 -> -17.989605 | K6: =COUNTIFS(Stundenpreise!$H$2:$H$17521,A6,Stundenpreise!$G$2:$G$17521,"ja")/COUNTIF(Stundenpreise!$H$2:$H$17521,A6) -> 0.081944444
A7: 2024-12 | B7: =ROUND(COUNTIF(Stundenpreise!$H$2:$H$17521,A7)/24,0) -> 31 | C7: =AVERAGEIF(Stundenpreise!$H$2:$H$17521,A7,Stundenpreise!$D$2:$D$17521)/10 -> 10.831559 | D7: =AVERAGEIF(Stundenpreise!$H$2:$H$17521,A7,Stundenpreise!$F$2:$F$17521) -> 35.090195 | E7: =SUMIF(Stundenpreise!$H$2:$H$17521,A7,Stundenpreise!$J$2:$J$17521)/SUMIF(Stundenpreise!$H$2:$H$17521,A7,Stundenpreise!$I$2:$I$17521) -> 35.958854 | F7: =Einstellungen!$B$5 -> 29 | G7: =Einstellungen!$B$9*B7/365 -> 297.26027 | H7: =G7*E7/100+(Einstellungen!$B$7+Einstellungen!$B$8/12)*B7/(365/12) -> 115.5544 | I7: =G7*F7/100+Einstellungen!$B$6*B7/(365/12) -> 98.435616 | J7: =I7-H7 -> -17.118784 | K7: =COUNTIFS(Stundenpreise!$H$2:$H$17521,A7,Stundenpreise!$G$2:$G$17521,"ja")/COUNTIF(Stundenpreise!$H$2:$H$17521,A7) -> 0.18548387
A8: 2025-01 | B8: =ROUND(COUNTIF(Stundenpreise!$H$2:$H$17521,A8)/24,0) -> 31 | C8: =AVERAGEIF(Stundenpreise!$H$2:$H$17521,A8,Stundenpreise!$D$2:$D$17521)/10 -> 11.414016 | D8: =AVERAGEIF(Stundenpreise!$H$2:$H$17521,A8,Stundenpreise!$F$2:$F$17521) -> 35.783319 | E8: =SUMIF(Stundenpreise!$H$2:$H$17521,A8,Stundenpreise!$J$2:$J$17521)/SUMIF(Stundenpreise!$H$2:$H$17521,A8,Stundenpreise!$I$2:$I$17521) -> 36.461777 | F8: =Einstellungen!$B$5 -> 29 | G8: =Einstellungen!$B$9*B8/365 -> 297.26027 | H8: =G8*E8/100+(Einstellungen!$B$7+Einstellungen!$B$8/12)*B8/(365/12) -> 117.04939 | I8: =G8*F8/100+Einstellungen!$B$6*B8/(365/12) -> 98.435616 | J8: =I8-H8 -> -18.613777 | K8: =COUNTIFS(Stundenpreise!$H$2:$H$17521,A8,Stundenpreise!$G$2:$G$17521,"ja")/COUNTIF(Stundenpreise!$H$2:$H$17521,A8) -> 0.11827957
A9: 2025-02 | B9: =ROUND(COUNTIF(Stundenpreise!$H$2:$H$17521,A9)/24,0) -> 28 | C9: =AVERAGEIF(Stundenpreise!$H$2:$H$17521,A9,Stundenpreise!$D$2:$D$17521)/10 -> 12.852237 | D9: =AVERAGEIF(Stundenpreise!$H$2:$H$17521,A9,Stundenpreise!$F$2:$F$17521) -> 37.494802 | E9: =SUMIF(Stundenpreise!$H$2:$H$17521,A9,Stundenpreise!$J$2:$J$17521)/SUMIF(Stundenpreise!$H$2:$H$17521,A9,Stundenpreise!$I$2:$I$17521) -> 38.014426 | F9: =Einstellungen!$B$5 -> 29 | G9: =Einstellungen!$B$9*B9/365 -> 268.49315 | H9: =G9*E9/100+(Einstellungen!$B$7+Einstellungen!$B$8/12)*B9/(365/12) -> 109.89079 | I9: =G9*F9/100+Einstellungen!$B$6*B9/(365/12) -> 88.909589 | J9: =I9-H9 -> -20.981198 | K9: =COUNTIFS(Stundenpreise!$H$2:$H$17521,A9,Stundenpreise!$G$2:$G$17521,"ja")/COUNTIF(Stundenpreise!$H$2:$H$17521,A9) -> 0.019345238
A10: 2025-03 | B10: =ROUND(COUNTIF(Stundenpreise!$H$2:$H$17521,A10)/24,0) -> 31 | C10: =AVERAGEIF(Stundenpreise!$H$2:$H$17521,A10,Stundenpreise!$D$2:$D$17521)/10 -> 9.4727497 | D10: =AVERAGEIF(Stundenpreise!$H$2:$H$17521,A10,Stundenpreise!$F$2:$F$17521) -> 33.473212 | E10: =SUMIF(Stundenpreise!$H$2:$H$17521,A10,Stundenpreise!$J$2:$J$17521)/SUMIF(Stundenpreise!$H$2:$H$17521,A10,Stundenpreise!$I$2:$I$17521) -> 33.742956 | F10: =Einstellungen!$B$5 -> 29 | G10: =Einstellungen!$B$9*B10/365 -> 297.26027 | H10: =G10*E10/100+(Einstellungen!$B$7+Einstellungen!$B$8/12)*B10/(365/12) -> 108.96742 | I10: =G10*F10/100+Einstellungen!$B$6*B10/(365/12) -> 98.435616 | J10: =I10-H10 -> -10.5318 | K10: =COUNTIFS(Stundenpreise!$H$2:$H$17521,A10,Stundenpreise!$G$2:$G$17521,"ja")/COUNTIF(Stundenpreise!$H$2:$H$17521,A10) -> 0.20323015
A11: 2025-04 | B11: =ROUND(COUNTIF(Stundenpreise!$H$2:$H$17521,A11)/24,0) -> 30 | C11: =AVERAGEIF(Stundenpreise!$H$2:$H$17521,A11,Stundenpreise!$D$2:$D$17521)/10 -> 7.7935653 | D11: =AVERAGEIF(Stundenpreise!$H$2:$H$17521,A11,Stundenpreise!$F$2:$F$17521) -> 31.474983 | E11: =SUMIF(Stundenpreise!$H$2:$H$17521,A11,Stundenpreise!$J$2:$J$17521)/SUMIF(Stundenpreise!$H$2:$H$17521,A11,Stundenpreise!$I$2:$I$17521) -> 31.547994 | F11: =Einstellungen!$B$5 -> 29 | G11: =Einstellungen!$B$9*B11/365 -> 287.67123 | H11: =G11*E11/100+(Einstellungen!$B$7+Einstellungen!$B$8/12)*B11/(365/12) -> 99.138064 | I11: =G11*F11/100+Einstellungen!$B$6*B11/(365/12) -> 95.260274 | J11: =I11-H11 -> -3.87779 | K11: =COUNTIFS(Stundenpreise!$H$2:$H$17521,A11,Stundenpreise!$G$2:$G$17521,"ja")/COUNTIF(Stundenpreise!$H$2:$H$17521,A11) -> 0.225
A12: 2025-05 | B12: =ROUND(COUNTIF(Stundenpreise!$H$2:$H$17521,A12)/24,0) -> 31 | C12: =AVERAGEIF(Stundenpreise!$H$2:$H$17521,A12,Stundenpreise!$D$2:$D$17521)/10 -> 6.7338629 | D12: =AVERAGEIF(Stundenpreise!$H$2:$H$17521,A12,Stundenpreise!$F$2:$F$17521) -> 30.213937 | E12: =SUMIF(Stundenpreise!$H$2:$H$17521,A12,Stundenpreise!$J$2:$J$17521)/SUMIF(Stundenpreise!$H$2:$H$17521,A12,Stundenpreise!$I$2:$I$17521) -> 30.101651 | F12: =Einstellungen!$B$5 -> 29 | G12: =Einstellungen!$B$9*B12/365 -> 297.26027 | H12: =G12*E12/100+(Einstellungen!$B$7+Einstellungen!$B$8/12)*B12/(365/12) -> 98.143264 | I12: =G12*F12/100+Einstellungen!$B$6*B12/(365/12) -> 98.435616 | J12: =I12-H12 -> 0.29235234 | K12: =COUNTIFS(Stundenpreise!$H$2:$H$17521,A12,Stundenpreise!$G$2:$G$17521,"ja")/COUNTIF(Stundenpreise!$H$2:$H$17521,A12) -> 0.3266129
A13: 2025-06 | B13: =ROUND(COUNTIF(Stundenpreise!$H$2:$H$17521,A13)/24,0) -> 30 | C13: =AVERAGEIF(Stundenpreise!$H$2:$H$17521,A13,Stundenpreise!$D$2:$D$17521)/10 -> 6.39875 | D13: =AVERAGEIF(Stundenpreise!$H$2:$H$17521,A13,Stundenpreise!$F$2:$F$17521) -> 29.815152 | E13: =SUMIF(Stundenpreise!$H$2:$H$17521,A13,Stundenpreise!$J$2:$J$17521)/SUMIF(Stundenpreise!$H$2:$H$17521,A13,Stundenpreise!$I$2:$I$17521) -> 29.70162 | F13: =Einstellungen!$B$5 -> 29 | G13: =Einstellungen!$B$9*B13/365 -> 287.67123 | H13: =G13*E13/100+(Einstellungen!$B$7+Einstellungen!$B$8/12)*B13/(365/12) -> 93.826577 | I13: =G13*F13/100+Einstellungen!$B$6*B13/(365/12) -> 95.260274 | J13: =I13-H13 -> 1.433697 | K13: =COUNTIFS(Stundenpreise!$H$2:$H$17521,A13,Stundenpreise!$G$2:$G$17521,"ja")/COUNTIF(Stundenpreise!$H$2:$H$17521,A13) -> 0.3625
A14: 2025-07 | B14: =ROUND(COUNTIF(Stundenpreise!$H$2:$H$17521,A14)/24,0) -> 31 | C14: =AVERAGEIF(Stundenpreise!$H$2:$H$17521,A14,Stundenpreise!$D$2:$D$17521)/10 -> 8.7795228 | D14: =AVERAGEIF(Stundenpreise!$H$2:$H$17521,A14,Stundenpreise!$F$2:$F$17521) -> 32.648272 | E14: =SUMIF(Stundenpreise!$H$2:$H$17521,A14,Stundenpreise!$J$2:$J$17521)/SUMIF(Stundenpreise!$H$2:$H$17521,A14,Stundenpreise!$I$2:$I$17521) -> 32.688279 | F14: =Einstellungen!$B$5 -> 29 | G14: =Einstellungen!$B$9*B14/365 -> 297.26027 | H14: =G14*E14/100+(Einstellungen!$B$7+Einstellungen!$B$8/12)*B14/(365/12) -> 105.83228 | I14: =G14*F14/100+Einstellungen!$B$6*B14/(365/12) -> 98.435616 | J14: =I14-H14 -> -7.3966649 | K14: =COUNTIFS(Stundenpreise!$H$2:$H$17521,A14,Stundenpreise!$G$2:$G$17521,"ja")/COUNTIF(Stundenpreise!$H$2:$H$17521,A14) -> 0.15725806
A15: 2025-08 | B15: =ROUND(COUNTIF(Stundenpreise!$H$2:$H$17521,A15)/24,0) -> 31 | C15: =AVERAGEIF(Stundenpreise!$H$2:$H$17521,A15,Stundenpreise!$D$2:$D$17521)/10 -> 7.6990255 | D15: =AVERAGEIF(Stundenpreise!$H$2:$H$17521,A15,Stundenpreise!$F$2:$F$17521) -> 31.36248 | E15: =SUMIF(Stundenpreise!$H$2:$H$17521,A15,Stundenpreise!$J$2:$J$17521)/SUMIF(Stundenpreise!$H$2:$H$17521,A15,Stundenpreise!$I$2:$I$17521) -> 31.412394 | F15: =Einstellungen!$B$5 -> 29 | G15: =Einstellungen!$B$9*B15/365 -> 297.26027 | H15: =G15*E15/100+(Einstellungen!$B$7+Einstellungen!$B$8/12)*B15/(365/12) -> 102.03958 | I15: =G15*F15/100+Einstellungen!$B$6*B15/(365/12) -> 98.435616 | J15: =I15-H15 -> -3.6039662 | K15: =COUNTIFS(Stundenpreise!$H$2:$H$17521,A15,Stundenpreise!$G$2:$G$17521,"ja")/COUNTIF(Stundenpreise!$H$2:$H$17521,A15) -> 0.25268817
A16: 2025-09 | B16: =ROUND(COUNTIF(Stundenpreise!$H$2:$H$17521,A16)/24,0) -> 30 | C16: =AVERAGEIF(Stundenpreise!$H$2:$H$17521,A16,Stundenpreise!$D$2:$D$17521)/10 -> 8.3511083 | D16: =AVERAGEIF(Stundenpreise!$H$2:$H$17521,A16,Stundenpreise!$F$2:$F$17521) -> 32.138459 | E16: =SUMIF(Stundenpreise!$H$2:$H$17521,A16,Stundenpreise!$J$2:$J$17521)/SUMIF(Stundenpreise!$H$2:$H$17521,A16,Stundenpreise!$I$2:$I$17521) -> 32.710824 | F16: =Einstellungen!$B$5 -> 29 | G16: =Einstellungen!$B$9*B16/365 -> 287.67123 | H16: =G16*E16/100+(Einstellungen!$B$7+Einstellungen!$B$8/12)*B16/(365/12) -> 102.48319 | I16: =G16*F16/100+Einstellungen!$B$6*B16/(365/12) -> 95.260274 | J16: =I16-H16 -> -7.2229192 | K16: =COUNTIFS(Stundenpreise!$H$2:$H$17521,A16,Stundenpreise!$G$2:$G$17521,"ja")/COUNTIF(Stundenpreise!$H$2:$H$17521,A16) -> 0.24861111
... A29: 2026-10 | B29: =ROUND(COUNTIF(Stundenpreise!$H$2:$H$17521,A29)/24,0) -> 15 | C29: =AVERAGEIF(Stundenpreise!$H$2:$H$17521,A29,Stundenpreise!$D$2:$D$17521)/10 -> 15.989291 | D29: =AVERAGEIF(Stundenpreise!$H$2:$H$17521,A29,Stundenpreise!$F$2:$F$17521) -> 41.227896 | E29: =SUMIF(Stundenpreise!$H$2:$H$17521,A29,Stundenpreise!$J$2:$J$17521)/SUMIF(Stundenpreise!$H$2:$H$17521,A29,Stundenpreise!$I$2:$I$17521) -> 41.840567 | F29: =Einstellungen!$B$5 -> 29 | G29: =Einstellungen!$B$9*B29/365 -> 143.83562 | H29: =G29*E29/100+(Einstellungen!$B$7+Einstellungen!$B$8/12)*B29/(365/12) -> 64.373418 | I29: =G29*F29/100+Einstellungen!$B$6*B29/(365/12) -> 47.630137 | J29: =I29-H29 -> -16.743281 | K29: =COUNTIFS(Stundenpreise!$H$2:$H$17521,A29,Stundenpreise!$G$2:$G$17521,"ja")/COUNTIF(Stundenpreise!$H$2:$H$17521,A29) -> 0.088888889
A30: Gesamt (2 Jahre) | B30: =SUM(B5:B29) -> 730 | C30: =AVERAGE(Stundenpreise!$D$2:$D$17521)/10 -> 9.9588239 | D30: =AVERAGE(Stundenpreise!$F$2:$F$17521) -> 34.05164 | E30: =SUMPRODUCT(E5:E29,G5:G29)/G30 -> 34.339019 | G30: =SUM(G5:G29) -> 7000 | H30: =SUM(H5:H29) -> 2607.7313 | I30: =SUM(I5:I29) -> 2318 | J30: =SUM(J5:J29) -> -289.7313 | K30: =COUNTIF(Stundenpreise!$G$2:$G$17521,"ja")/COUNT(Stundenpreise!$D$2:$D$17521) -> 0.17893836
A32: Fazit
A33: Ersparnis pro Jahr mit dynamischem Tarif (Ø) | B33: =J30/(B30/365) -> -144.86565
A34: Ergebnis | B34: =IF(J30>0,"Dynamisch wäre günstiger gewesen","Dein Festpreis war günstiger") -> Dein Festpreis war günstiger
A35: Annahmen (Verbrauch, Netzentgelt, Grundpreise, Tagesprofil) im Blatt „Einstellungen“ anpassen – alles rechnet sich neu.

Sheet Einstellungen
A1: Dynamischer Stromtarif vs. Festpreis – Einstellungen
A2: Gelb hinterlegte, blaue Zellen kannst du ändern – alles andere rechnet sich automatisch neu.
A4: Eingaben
A5: Dein Festpreis (brutto, ct/kWh) | B5: 29 | C5: Laut deiner Angabe
A6: Grundpreis Festtarif (brutto, €/Monat) | B6: 12 | C6: Annahme – bitte aus deinem Vertrag eintragen
A7: Grundpreis dynamischer Tarif (brutto, €/Monat) | B7: 6 | C7: Annahme, z.B. Anbietergebühr (Tibber ~6 €, Rabot ~ähnlich)
A8: Smart-Meter-Mehrkosten (brutto, €/Jahr) | B8: 30 | C8: Annahme – dynamische Tarife brauchen ein intelligentes Messsystem; Kosten je nach Messstellenbetreiber
A9: Jahresverbrauch (kWh) | B9: 3500 | C9: Annahme – bitte deinen Verbrauch eintragen
A10: Mehrwertsteuer | B10: 0.19 | C10: 19 %
A12: Aufschläge auf den Börsenpreis (netto, ct/kWh)
A13: Netzentgelt (Arbeitspreis) | B13: 10.5 | C13: Annahme: grober Bundesdurchschnitt; regional sehr unterschiedlich (ca. 7–15 ct) – steht auf deiner Rechnung
A14: Stromsteuer | B14: 2.05 | C14: Gesetzlich (StromStG)
A15: Konzessionsabgabe | B15: 1.66 | C15: Typischer Wert für Gemeinden >100.000 EW; kleinere Gemeinden 1,32–1,59
A16: KWKG-Umlage | B16: 0.446 | C16: Wert 2026 (netztransparenz.de)
A17: §19 StromNEV-Umlage | B17: 1.559 | C17: Wert 2026 (netztransparenz.de)
A18: Offshore-Netzumlage | B18: 0.941 | C18: Wert 2026 (netztransparenz.de)
A19: Anbieter-Aufschlag / Marge | B19: 1.5 | C19: Annahme – je nach Anbieter ca. 0–3 ct
A20: Summe Aufschläge netto | B20: =SUM(B13:B19) -> 18.656
A22: Hinweis: Die Aufschläge werden vereinfacht für den ganzen Zeitraum gleich angesetzt (Werte 2026). Endpreis brutto = (Börsenpreis + Aufschläge) × (1 + MwSt). Negative Börsenpreise senken den Endpreis entsprechend.
A24: Verbrauchsprofil über den Tag (relatives Gewicht je Stunde)
A25: Vereinfachtes Haushaltsprofil ähnlich Standardlastprofil H0: wenig nachts, Spitze abends. Wer z.B. E-Auto/Wärmepumpe nachts lädt, kann die Gewichte anpassen.
A26: Stunde | B26: Gewicht
A27: 00:00–00:59 | B27: 0.6
A28: 01:00–01:59 | B28: 0.5
A29: 02:00–02:59 | B29: 0.45
A30: 03:00–03:59 | B30: 0.45
A31: 04:00–04:59 | B31: 0.45
A32: 05:00–05:59 | B32: 0.5
A33: 06:00–06:59 | B33: 0.7
A34: 07:00–07:59 | B34: 0.95
A35: 08:00–08:59 | B35: 1.05
A36: 09:00–09:59 | B36: 1.05
A37: 10:00–10:59 | B37: 1.05
A38: 11:00–11:59 | B38: 1.1
... A50: 23:00–23:59 | B50: 0.8
A52: Datenquelle: Day-Ahead-Börsenpreise Gebotszone DE-LU (EPEX Spot), via Energy-Charts (Fraunhofer ISE), Lizenz CC BY 4.0, Daten: Bundesnetzagentur | SMARD.de. Seit 01.10.2025 handelt die Börse in 15-Minuten-Schritten – diese Werte sind hier zu Stundenmittelwerten zusammengefasst.

Sheet Stundenpreise
A1: Datum | B1: Uhrzeit | C1: Wochentag | D1: Börsenpreis (€/MWh) | E1: Börsenpreis (ct/kWh netto) | F1: Endpreis dynamisch (ct/kWh brutto) | G1: Günstiger als Festpreis? | H1: Monat | I1: Verbrauchsgewicht | J1: Preis × Gewicht
A2: 45581 | B2: 00:00 | C2: Mi | D2: 23.35 | E2: =D2/10 -> 2.335 | F2: =(E2+Einstellungen!$B$20)*(1+Einstellungen!$B$10) -> 24.97929 | G2: =IF(F2<Einstellungen!$B$5,"ja","nein") -> ja | H2: 2024-10 | I2: =INDEX(Einstellungen!$B$27:$B$50,1) -> 0.6 | J2: =F2*I2 -> 14.987574
A3: 45581 | B3: 01:00 | C3: Mi | D3: 12.8 | E3: =D3/10 -> 1.28 | F3: =(E3+Einstellungen!$B$20)*(1+Einstellungen!$B$10) -> 23.72384 | G3: =IF(F3<Einstellungen!$B$5,"ja","nein") -> ja | H3: 2024-10 | I3: =INDEX(Einstellungen!$B$27:$B$50,2) -> 0.5 | J3: =F3*I3 -> 11.86192
A4: 45581 | B4: 02:00 | C4: Mi | D4: 5.3 | E4: =D4/10 -> 0.53 | F4: =(E4+Einstellungen!$B$20)*(1+Einstellungen!$B$10) -> 22.83134 | G4: =IF(F4<Einstellungen!$B$5,"ja","nein") -> ja | H4: 2024-10 | I4: =INDEX(Einstellungen!$B$27:$B$50,3) -> 0.45 | J4: =F4*I4 -> 10.274103
A5: 45581 | B5: 03:00 | C5: Mi | D5: 3.61 | E5: =D5/10 -> 0.361 | F5: =(E5+Einstellungen!$B$20)*(1+Einstellungen!$B$10) -> 22.63023 | G5: =IF(F5<Einstellungen!$B$5,"ja","nein") -> ja | H5: 2024-10 | I5: =INDEX(Einstellungen!$B$27:$B$50,4) -> 0.45 | J5: =F5*I5 -> 10.183604
A6: 45581 | B6: 04:00 | C6: Mi | D6: 3.16 | E6: =D6/10 -> 0.316 | F6: =(E6+Einstellungen!$B$20)*(1+Einstellungen!$B$10) -> 22.57668 | G6: =IF(F6<Einstellungen!$B$5,"ja","nein") -> ja | H6: 2024-10 | I6: =INDEX(Einstellungen!$B$27:$B$50,5) -> 0.45 | J6: =F6*I6 -> 10.159506
A7: 45581 | B7: 05:00 | C7: Mi | D7: 8.2 | E7: =D7/10 -> 0.82 | F7: =(E7+Einstellungen!$B$20)*(1+Einstellungen!$B$10) -> 23.17644 | G7: =IF(F7<Einstellungen!$B$5,"ja","nein") -> ja | H7: 2024-10 | I7: =INDEX(Einstellungen!$B$27:$B$50,6) -> 0.5 | J7: =F7*I7 -> 11.58822
A8: 45581 | B8: 06:00 | C8: Mi | D8: 42.59 | E8: =D8/10 -> 4.259 | F8: =(E8+Einstellungen!$B$20)*(1+Einstellungen!$B$10) -> 27.26885 | G8: =IF(F8<Einstellungen!$B$5,"ja","nein") -> ja | H8: 2024-10 | I8: =INDEX(Einstellungen!$B$27:$B$50,7) -> 0.7 | J8: =F8*I8 -> 19.088195
A9: 45581 | B9: 07:00 | C9: Mi | D9: 67.29 | E9: =D9/10 -> 6.729 | F9: =(E9+Einstellungen!$B$20)*(1+Einstellungen!$B$10) -> 30.20815 | G9: =IF(F9<Einstellungen!$B$5,"ja","nein") -> nein | H9: 2024-10 | I9: =INDEX(Einstellungen!$B$27:$B$50,8) -> 0.95 | J9: =F9*I9 -> 28.697743
A10: 45581 | B10: 08:00 | C10: Mi | D10: 66.52 | E10: =D10/10 -> 6.652 | F10: =(E10+Einstellungen!$B$20)*(1+Einstellungen!$B$10) -> 30.11652 | G10: =IF(F10<Einstellungen!$B$5,"ja","nein") -> nein | H10: 2024-10 | I10: =INDEX(Einstellungen!$B$27:$B$50,9) -> 1.05 | J10: =F10*I10 -> 31.622346
A11: 45581 | B11: 09:00 | C11: Mi | D11: 54.29 | E11: =D11/10 -> 5.429 | F11: =(E11+Einstellungen!$B$20)*(1+Einstellungen!$B$10) -> 28.66115 | G11: =IF(F11<Einstellungen!$B$5,"ja","nein") -> ja | H11: 2024-10 | I11: =INDEX(Einstellungen!$B$27:$B$50,10) -> 1.05 | J11: =F11*I11 -> 30.094207
A12: 45581 | B12: 10:00 | C12: Mi | D12: 26.68 | E12: =D12/10 -> 2.668 | F12: =(E12+Einstellungen!$B$20)*(1+Einstellungen!$B$10) -> 25.37556 | G12: =IF(F12<Einstellungen!$B$5,"ja","nein") -> ja | H12: 2024-10 | I12: =INDEX(Einstellungen!$B$27:$B$50,11) -> 1.05 | J12: =F12*I12 -> 26.644338
A13: 45581 | B13: 11:00 | C13: Mi | D13: 14.16 | E13: =D13/10 -> 1.416 | F13: =(E13+Einstellungen!$B$20)*(1+Einstellungen!$B$10) -> 23.88568 | G13: =IF(F13<Einstellungen!$B$5,"ja","nein") -> ja | H13: 2024-10 | I13: =INDEX(Einstellungen!$B$27:$B$50,12) -> 1.1 | J13: =F13*I13 -> 26.274248
A14: 45581 | B14: 12:00 | C14: Mi | D14: 4.09 | E14: =D14/10 -> 0.409 | F14: =(E14+Einstellungen!$B$20)*(1+Einstellungen!$B$10) -> 22.68735 | G14: =IF(F14<Einstellungen!$B$5,"ja","nein") -> ja | H14: 2024-10 | I14: =INDEX(Einstellungen!$B$27:$B$50,13) -> 1.2 | J14: =F14*I14 -> 27.22482
A15: 45581 | B15: 13:00 | C15: Mi | D15: 2.04 | E15: =D15/10 -> 0.204 | F15: =(E15+Einstellungen!$B$20)*(1+Einstellungen!$B$10) -> 22.4434 | G15: =IF(F15<Einstellungen!$B$5,"ja","nein") -> ja | H15: 2024-10 | I15: =INDEX(Einstellungen!$B$27:$B$50,14) -> 1.15 | J15: =F15*I15 -> 25.80991
A16: 45581 | B16: 14:00 | C16: Mi | D16: 4 | E16: =D16/10 -> 0.4 | F16: =(E16+Einstellungen!$B$20)*(1+Einstellungen!$B$10) -> 22.67664 | G16: =IF(F16<Einstellungen!$B$5,"ja","nein") -> ja | H16: 2024-10 | I16: =INDEX(Einstellungen!$B$27:$B$50,15) -> 1 | J16: =F16*I16 -> 22.67664
A17: 45581 | B17: 15:00 | C17: Mi | D17: 14.18 | E17: =D17/10 -> 1.418 | F17: =(E17+Einstellungen!$B$20)*(1+Einstellungen!$B$10) -> 23.88806 | G17: =IF(F17<Einstellungen!$B$5,"ja","nein") -> ja | H17: 2024-10 | I17: =INDEX(Einstellungen!$B$27:$B$50,16) -> 0.95 | J17: =F17*I17 -> 22.693657
A18: 45581 | B18: 16:00 | C18: Mi | D18: 54.92 | E18: =D18/10 -> 5.492 | F18: =(E18+Einstellungen!$B$20)*(1+Einstellungen!$B$10) -> 28.73612 | G18: =IF(F18<Einstellungen!$B$5,"ja","nein") -> ja | H18: 2024-10 | I18: =INDEX(Einstellungen!$B$27:$B$50,17) -> 0.95 | J18: =F18*I18 -> 27.299314
A19: 45581 | B19: 17:00 | C19: Mi | D19: 72.95 | E19: =D19/10 -> 7.295 | F19: =(E19+Einstellungen!$B$20)*(1+Einstellungen!$B$10) -> 30.88169 | G19: =IF(F19<Einstellungen!$B$5,"ja","nein") -> nein | H19: 2024-10 | I19: =INDEX(Einstellungen!$B$27:$B$50,18) -> 1.1 | J19: =F19*I19 -> 33.969859
A20: 45581 | B20: 18:00 | C20: Mi | D20: 84.47 | E20: =D20/10 -> 8.447 | F20: =(E20+Einstellungen!$B$20)*(1+Einstellungen!$B$10) -> 32.25257 | G20: =IF(F20<Einstellungen!$B$5,"ja","nein") -> nein | H20: 2024-10 | I20: =INDEX(Einstellungen!$B$27:$B$50,19) -> 1.35 | J20: =F20*I20 -> 43.54097
A21: 45581 | B21: 19:00 | C21: Mi | D21: 88.38 | E21: =D21/10 -> 8.838 | F21: =(E21+Einstellungen!$B$20)*(1+Einstellungen!$B$10) -> 32.71786 | G21: =IF(F21<Einstellungen!$B$5,"ja","nein") -> nein | H21: 2024-10 | I21: =INDEX(Einstellungen!$B$27:$B$50,20) -> 1.45 | J21: =F21*I21 -> 47.440897
A22: 45581 | B22: 20:00 | C22: Mi | D22: 65.31 | E22: =D22/10 -> 6.531 | F22: =(E22+Einstellungen!$B$20)*(1+Einstellungen!$B$10) -> 29.97253 | G22: =IF(F22<Einstellungen!$B$5,"ja","nein") -> nein | H22: 2024-10 | I22: =INDEX(Einstellungen!$B$27:$B$50,21) -> 1.4 | J22: =F22*I22 -> 41.961542
A23: 45581 | B23: 21:00 | C23: Mi | D23: 61.86 | E23: =D23/10 -> 6.186 | F23: =(E23+Einstellungen!$B$20)*(1+Einstellungen!$B$10) -> 29.56198 | G23: =IF(F23<Einstellungen!$B$5,"ja","nein") -> nein | H23: 2024-10 | I23: =INDEX(Einstellungen!$B$27:$B$50,22) -> 1.25 | J23: =F23*I23 -> 36.952475
A24: 45581 | B24: 22:00 | C24: Mi | D24: 35.14 | E24: =D24/10 -> 3.514 | F24: =(E24+Einstellungen!$B$20)*(1+Einstellungen!$B$10) -> 26.3823 | G24: =IF(F24<Einstellungen!$B$5,"ja","nein") -> ja | H24: 2024-10 | I24: =INDEX(Einstellungen!$B$27:$B$50,23) -> 1.05 | J24: =F24*I24 -> 27.701415
A25: 45581 | B25: 23:00 | C25: Mi | D25: 26.54 | E25: =D25/10 -> 2.654 | F25: =(E25+Einstellungen!$B$20)*(1+Einstellungen!$B$10) -> 25.3589 | G25: =IF(F25<Einstellungen!$B$5,"ja","nein") -> ja | H25: 2024-10 | I25: =INDEX(Einstellungen!$B$27:$B$50,24) -> 0.8 | J25: =F25*I25 -> 20.28712
A26: 45582 | B26: 00:00 | C26: Do | D26: 17.04 | E26: =D26/10 -> 1.704 | F26: =(E26+Einstellungen!$B$20)*(1+Einstellungen!$B$10) -> 24.2284 | G26: =IF(F26<Einstellungen!$B$5,"ja","nein") -> ja | H26: 2024-10 | I26: =INDEX(Einstellungen!$B$27:$B$50,1) -> 0.6 | J26: =F26*I26 -> 14.53704
A27: 45582 | B27: 01:00 | C27: Do | D27: 12.15 | E27: =D27/10 -> 1.215 | F27: =(E27+Einstellungen!$B$20)*(1+Einstellungen!$B$10) -> 23.64649 | G27: =IF(F27<Einstellungen!$B$5,"ja","nein") -> ja | H27: 2024-10 | I27: =INDEX(Einstellungen!$B$27:$B$50,2) -> 0.5 | J27: =F27*I27 -> 11.823245
A28: 45582 | B28: 02:00 | C28: Do | D28: 10.48 | E28: =D28/10 -> 1.048 | F28: =(E28+Einstellungen!$B$20)*(1+Einstellungen!$B$10) -> 23.44776 | G28: =IF(F28<Einstellungen!$B$5,"ja","nein") -> ja | H28: 2024-10 | I28: =INDEX(Einstellungen!$B$27:$B$50,3) -> 0.45 | J28: =F28*I28 -> 10.551492
A29: 45582 | B29: 03:00 | C29: Do | D29: 5.61 | E29: =D29/10 -> 0.561 | F29: =(E29+Einstellungen!$B$20)*(1+Einstellungen!$B$10) -> 22.86823 | G29: =IF(F29<Einstellungen!$B$5,"ja","nein") -> ja | H29: 2024-10 | I29: =INDEX(Einstellungen!$B$27:$B$50,4) -> 0.45 | J29: =F29*I29 -> 10.290703
A30: 45582 | B30: 04:00 | C30: Do | D30: 10.01 | E30: =D30/10 -> 1.001 | F30: =(E30+Einstellungen!$B$20)*(1+Einstellungen!$B$10) -> 23.39183 | G30: =IF(F30<Einstellungen!$B$5,"ja","nein") -> ja | H30: 2024-10 | I30: =INDEX(Einstellungen!$B$27:$B$50,5) -> 0.45 | J30: =F30*I30 -> 10.526324
A31: 45582 | B31: 05:00 | C31: Do | D31: 29.8 | E31: =D31/10 -> 2.98 | F31: =(E31+Einstellungen!$B$20)*(1+Einstellungen!$B$10) -> 25.74684 | G31: =IF(F31<Einstellungen!$B$5,"ja","nein") -> ja | H31: 2024-10 | I31: =INDEX(Einstellungen!$B$27:$B$50,6) -> 0.5 | J31: =F31*I31 -> 12.87342
A32: 45582 | B32: 06:00 | C32: Do | D32: 70.51 | E32: =D32/10 -> 7.051 | F32: =(E32+Einstellungen!$B$20)*(1+Einstellungen!$B$10) -> 30.59133 | G32: =IF(F32<Einstellungen!$B$5,"ja","nein") -> nein | H32: 2024-10 | I32: =INDEX(Einstellungen!$B$27:$B$50,7) -> 0.7 | J32: =F32*I32 -> 21.413931
A33: 45582 | B33: 07:00 | C33: Do | D33: 101.39 | E33: =D33/10 -> 10.139 | F33: =(E33+Einstellungen!$B$20)*(1+Einstellungen!$B$10) -> 34.26605 | G33: =IF(F33<Einstellungen!$B$5,"ja","nein") -> nein | H33: 2024-10 | I33: =INDEX(Einstellungen!$B$27:$B$50,8) -> 0.95 | J33: =F33*I33 -> 32.552748
A34: 45582 | B34: 08:00 | C34: Do | D34: 92.53 | E34: =D34/10 -> 9.253 | F34: =(E34+Einstellungen!$B$20)*(1+Einstellungen!$B$10) -> 33.21171 | G34: =IF(F34<Einstellungen!$B$5,"ja","nein") -> nein | H34: 2024-10 | I34: =INDEX(Einstellungen!$B$27:$B$50,9) -> 1.05 | J34: =F34*I34 -> 34.872295
A35: 45582 | B35: 09:00 | C35: Do | D35: 73.76 | E35: =D35/10 -> 7.376 | F35: =(E35+Einstellungen!$B$20)*(1+Einstellungen!$B$10) -> 30.97808 | G35: =IF(F35<Einstellungen!$B$5,"ja","nein") -> nein | H35: 2024-10 | I35: =INDEX(Einstellungen!$B$27:$B$50,10) -> 1.05 | J35: =F35*I35 -> 32.526984
A36: 45582 | B36: 10:00 | C36: Do | D36: 62.22 | E36: =D36/10 -> 6.222 | F36: =(E36+Einstellungen!$B$20)*(1+Einstellungen!$B$10) -> 29.60482 | G36: =IF(F36<Einstellungen!$B$5,"ja","nein") -> nein | H36: 2024-10 | I36: =INDEX(Einstellungen!$B$27:$B$50,11) -> 1.05 | J36: =F36*I36 -> 31.085061
A37: 45582 | B37: 11:00 | C37: Do | D37: 52.02 | E37: =D37/10 -> 5.202 | F37: =(E37+Einstellungen!$B$20)*(1+Einstellungen!$B$10) -> 28.39102 | G37: =IF(F37<Einstellungen!$B$5,"ja","nein") -> ja | H37: 2024-10 | I37: =INDEX(Einstellungen!$B$27:$B$50,12) -> 1.1 | J37: =F37*I37 -> 31.230122
A38: 45582 | B38: 12:00 | C38: Do | D38: 46.54 | E38: =D38/10 -> 4.654 | F38: =(E38+Einstellungen!$B$20)*(1+Einstellungen!$B$10) -> 27.7389 | G38: =IF(F38<Einstellungen!$B$5,"ja","nein") -> ja | H38: 2024-10 | I38: =INDEX(Einstellungen!$B$27:$B$50,13) -> 1.2 | J38: =F38*I38 -> 33.28668
A39: 45582 | B39: 13:00 | C39: Do | D39: 47.52 | E39: =D39/10 -> 4.752 | F39: =(E39+Einstellungen!$B$20)*(1+Einstellungen!$B$10) -> 27.85552 | G39: =IF(F39<Einstellungen!$B$5,"ja","nein") -> ja | H39: 2024-10 | I39: =INDEX(Einstellungen!$B$27:$B$50,14) -> 1.15 | J39: =F39*I39 -> 32.033848
A40: 45582 | B40: 14:00 | C40: Do | D40: 60.04 | E40: =D40/10 -> 6.004 | F40: =(E40+Einstellungen!$B$20)*(1+Einstellungen!$B$10) -> 29.3454 | G40: =IF(F40<Einstellungen!$B$5,"ja","nein") -> nein | H40: 2024-10 | I40: =INDEX(Einstellungen!$B$27:$B$50,15) -> 1 | J40: =F40*I40 -> 29.3454
...
